2019-07-10 22:15:04,707 [django.request:135] [exception:handle_uncaught_exception] [ERROR] Internal Server Error: /admin/login/
Traceback (most recent call last):
  File "D:\python\python_code\blog_project\venv\lib\site-packages\django\core\handlers\exception.py", line 41, in inner
    response = get_response(request)
  File "D:\python\python_code\blog_project\venv\lib\site-packages\django\core\handlers\base.py", line 187, in _get_response
    response = self.process_exception_by_middleware(e, request)
  File "D:\python\python_code\blog_project\venv\lib\site-packages\django\core\handlers\base.py", line 185, in _get_response
    response = wrapped_callback(request, *callback_args, **callback_kwargs)
  File "D:\python\python_code\blog_project\venv\lib\site-packages\django\views\decorators\cache.py", line 57, in _wrapped_view_func
    response = view_func(request, *args, **kwargs)
  File "D:\python\python_code\blog_project\venv\lib\site-packages\django\contrib\admin\sites.py", line 393, in login
    return LoginView.as_view(**defaults)(request)
  File "D:\python\python_code\blog_project\venv\lib\site-packages\django\views\generic\base.py", line 68, in view
    return self.dispatch(request, *args, **kwargs)
  File "D:\python\python_code\blog_project\venv\lib\site-packages\django\utils\decorators.py", line 67, in _wrapper
    return bound_func(*args, **kwargs)
  File "D:\python\python_code\blog_project\venv\lib\site-packages\django\views\decorators\debug.py", line 76, in sensitive_post_parameters_wrapper
    return view(request, *args, **kwargs)
  File "D:\python\python_code\blog_project\venv\lib\site-packages\django\utils\decorators.py", line 63, in bound_func
    return func.__get__(self, type(self))(*args2, **kwargs2)
  File "D:\python\python_code\blog_project\venv\lib\site-packages\django\utils\decorators.py", line 67, in _wrapper
    return bound_func(*args, **kwargs)
  File "D:\python\python_code\blog_project\venv\lib\site-packages\django\utils\decorators.py", line 149, in _wrapped_view
    response = view_func(request, *args, **kwargs)
  File "D:\python\python_code\blog_project\venv\lib\site-packages\django\utils\decorators.py", line 63, in bound_func
    return func.__get__(self, type(self))(*args2, **kwargs2)
  File "D:\python\python_code\blog_project\venv\lib\site-packages\django\utils\decorators.py", line 67, in _wrapper
    return bound_func(*args, **kwargs)
  File "D:\python\python_code\blog_project\venv\lib\site-packages\django\views\decorators\cache.py", line 57, in _wrapped_view_func
    response = view_func(request, *args, **kwargs)
  File "D:\python\python_code\blog_project\venv\lib\site-packages\django\utils\decorators.py", line 63, in bound_func
    return func.__get__(self, type(self))(*args2, **kwargs2)
  File "D:\python\python_code\blog_project\venv\lib\site-packages\django\contrib\auth\views.py", line 90, in dispatch
    return super(LoginView, self).dispatch(request, *args, **kwargs)
  File "D:\python\python_code\blog_project\venv\lib\site-packages\django\views\generic\base.py", line 88, in dispatch
    return handler(request, *args, **kwargs)
  File "D:\python\python_code\blog_project\venv\lib\site-packages\django\views\generic\edit.py", line 182, in post
    if form.is_valid():
  File "D:\python\python_code\blog_project\venv\lib\site-packages\django\forms\forms.py", line 183, in is_valid
    return self.is_bound and not self.errors
  File "D:\python\python_code\blog_project\venv\lib\site-packages\django\forms\forms.py", line 175, in errors
    self.full_clean()
  File "D:\python\python_code\blog_project\venv\lib\site-packages\django\forms\forms.py", line 385, in full_clean
    self._clean_form()
  File "D:\python\python_code\blog_project\venv\lib\site-packages\django\forms\forms.py", line 412, in _clean_form
    cleaned_data = self.clean()
  File "D:\python\python_code\blog_project\venv\lib\site-packages\django\contrib\auth\forms.py", line 187, in clean
    self.user_cache = authenticate(self.request, username=username, password=password)
  File "D:\python\python_code\blog_project\venv\lib\site-packages\django\contrib\auth\__init__.py", line 70, in authenticate
    user = _authenticate_with_backend(backend, backend_path, request, credentials)
  File "D:\python\python_code\blog_project\venv\lib\site-packages\django\contrib\auth\__init__.py", line 116, in _authenticate_with_backend
    return backend.authenticate(*args, **credentials)
  File "D:\python\python_code\blog_project\venv\lib\site-packages\django\contrib\auth\backends.py", line 18, in authenticate
    user = UserModel._default_manager.get_by_natural_key(username)
  File "D:\python\python_code\blog_project\venv\lib\site-packages\django\contrib\auth\base_user.py", line 48, in get_by_natural_key
    return self.get(**{self.model.USERNAME_FIELD: username})
  File "D:\python\python_code\blog_project\venv\lib\site-packages\django\db\models\manager.py", line 85, in manager_method
    return getattr(self.get_queryset(), name)(*args, **kwargs)
  File "D:\python\python_code\blog_project\venv\lib\site-packages\django\db\models\query.py", line 374, in get
    num = len(clone)
  File "D:\python\python_code\blog_project\venv\lib\site-packages\django\db\models\query.py", line 232, in __len__
    self._fetch_all()
  File "D:\python\python_code\blog_project\venv\lib\site-packages\django\db\models\query.py", line 1121, in _fetch_all
    self._result_cache = list(self._iterable_class(self))
  File "D:\python\python_code\blog_project\venv\lib\site-packages\django\db\models\query.py", line 53, in __iter__
    results = compiler.execute_sql(chunked_fetch=self.chunked_fetch)
  File "D:\python\python_code\blog_project\venv\lib\site-packages\django\db\models\sql\compiler.py", line 899, in execute_sql
    raise original_exception
OperationalError: no such table: auth_user
